Traceback (most recent call last):
  File "D:\Task Management System Final code\Checklist\checklist_status.py", line 74, in update_Status
    propagate_incomplete_upwards(data.checklist_id, db, Current_user)
  File "D:\Task Management System Final code\Checklist\functions.py", line 143, in propagate_incomplete_upwards
    task.status = TaskStatus(last_status_log.old_value)
                  ^^^^^^^^^^^^^^^^^^^^^^^^^^^^^^^^^^^^^
  File "C:\Users\BARANEEDHARAN\AppData\Local\Programs\Python\Python312\Lib\enum.py", line 751, in __call__
    return cls.__new__(cls, value)
           ^^^^^^^^^^^^^^^^^^^^^^^
  File "C:\Users\BARANEEDHARAN\AppData\Local\Programs\Python\Python312\Lib\enum.py", line 1165, in __new__
    raise ve_exc
ValueError: 'None' is not a valid TaskStatus
Traceback (most recent call last):
  File "D:\Task Management System Final code\Checklist\checklist_status.py", line 99, in update_Status
    propagate_incomplete_upwards(data.checklist_id, db, Current_user)
  File "D:\Task Management System Final code\Checklist\functions.py", line 128, in propagate_incomplete_upwards
    print(parent_tasks.task_id)
          ^^^^^^^^^^^^^^^^^^^^
AttributeError: 'list' object has no attribute 'task_id'
Traceback (most recent call last):
  File "D:\Task Management System Final code\.venv\Lib\site-packages\sqlalchemy\engine\result.py", line 199, in _key_not_found
    self._key_fallback(key, None)
  File "D:\Task Management System Final code\.venv\Lib\site-packages\sqlalchemy\engine\result.py", line 138, in _key_fallback
    raise KeyError(key) from err
KeyError: 'task_id'

The above exception was the direct cause of the following exception:

Traceback (most recent call last):
  File "D:\Task Management System Final code\Checklist\checklist_status.py", line 99, in update_Status
    propagate_incomplete_upwards(data.checklist_id, db, Current_user)
  File "D:\Task Management System Final code\Checklist\functions.py", line 128, in propagate_incomplete_upwards
    print(parent_tasks.task_id)
          ^^^^^^^^^^^^^^^^^^^^
  File "lib\\sqlalchemy\\cyextension\\resultproxy.pyx", line 66, in sqlalchemy.cyextension.resultproxy.BaseRow.__getattr__
  File "lib\\sqlalchemy\\cyextension\\resultproxy.pyx", line 63, in sqlalchemy.cyextension.resultproxy.BaseRow._get_by_key_impl
  File "D:\Task Management System Final code\.venv\Lib\site-packages\sqlalchemy\engine\result.py", line 201, in _key_not_found
    raise AttributeError(ke.args[0]) from ke
AttributeError: task_id
Traceback (most recent call last):
  File "D:\Task Management System Final code\Checklist\checklist_status.py", line 99, in update_Status
    propagate_incomplete_upwards(data.checklist_id, db, Current_user)
  File "D:\Task Management System Final code\Checklist\functions.py", line 131, in propagate_incomplete_upwards
    parent_task_id = pt[0]
                     ~~^^^
TypeError: 'int' object is not subscriptable
Traceback (most recent call last):
  File "D:\Task Management System Final code\Checklist\checklist_status.py", line 99, in update_Status
    propagate_incomplete_upwards(data.checklist_id, db, Current_user)
  File "D:\Task Management System Final code\Checklist\functions.py", line 130, in propagate_incomplete_upwards
    parent_task_id = pt[0]
                     ^^
NameError: name 'pt' is not defined
Traceback (most recent call last):
  File "D:\Task Management System Final code\Checklist\checklist_status.py", line 97, in update_Status
    update_parent_task_status(parent_task_id, db, Current_user)
  File "D:\Task Management System Final code\Checklist\functions.py", line 37, in update_parent_task_status
    review_task.previous_status = review_task.status
                                  ^^^^^^^^^^^^^^^^^^
AttributeError: 'NoneType' object has no attribute 'status'
Traceback (most recent call last):
  File "D:\Task Management System Final code\Checklist\checklist_status.py", line 97, in update_Status
    update_parent_task_status(parent_task_id, db, Current_user)
  File "D:\Task Management System Final code\Checklist\functions.py", line 37, in update_parent_task_status
    review_task.previous_status = review_task.status if review_task.status is not None else "To_Do"
                                                        ^^^^^^^^^^^^^^^^^^
AttributeError: 'NoneType' object has no attribute 'status'
Traceback (most recent call last):
  File "D:\Task Management System Final code\Checklist\checklist_status.py", line 97, in update_Status
    update_parent_task_status(parent_task_id, db, Current_user)
  File "D:\Task Management System Final code\Checklist\functions.py", line 37, in update_parent_task_status
    review_task.previous_status = review_task.status if review_task.status is not None else "To_Do"
                                                        ^^^^^^^^^^^^^^^^^^
AttributeError: 'NoneType' object has no attribute 'status'
Traceback (most recent call last):
  File "D:\Task Management System Final code\Checklist\checklist_status.py", line 97, in update_Status
    update_parent_task_status(parent_task_id, db, Current_user)
  File "D:\Task Management System Final code\Checklist\functions.py", line 37, in update_parent_task_status
    review_task.previous_status = review_task.status if review_task and review_task.status is not None else "To_Do"
    ^^^^^^^^^^^^^^^^^^^^^^^^^^^
AttributeError: 'NoneType' object has no attribute 'previous_status'
Traceback (most recent call last):
  File "D:\Task Management System Final code\Checklist\checklist_status.py", line 97, in update_Status
    update_parent_task_status(parent_task_id, db, Current_user)
  File "D:\Task Management System Final code\Checklist\functions.py", line 36, in update_parent_task_status
    if review_task is not None:
       ^^^^^^^^^^^
UnboundLocalError: cannot access local variable 'review_task' where it is not associated with a value
Traceback (most recent call last):
  File "D:\Task Management System Final code\.venv\Lib\site-packages\sqlalchemy\engine\base.py", line 1964, in _exec_single_context
    self.dialect.do_execute(
  File "D:\Task Management System Final code\.venv\Lib\site-packages\sqlalchemy\engine\default.py", line 945, in do_execute
    cursor.execute(statement, parameters)
  File "D:\Task Management System Final code\.venv\Lib\site-packages\pymysql\cursors.py", line 153, in execute
    result = self._query(query)
             ^^^^^^^^^^^^^^^^^^
  File "D:\Task Management System Final code\.venv\Lib\site-packages\pymysql\cursors.py", line 322, in _query
    conn.query(q)
  File "D:\Task Management System Final code\.venv\Lib\site-packages\pymysql\connections.py", line 563, in query
    self._affected_rows = self._read_query_result(unbuffered=unbuffered)
                          ^^^^^^^^^^^^^^^^^^^^^^^^^^^^^^^^^^^^^^^^^^^^^^
  File "D:\Task Management System Final code\.venv\Lib\site-packages\pymysql\connections.py", line 825, in _read_query_result
    result.read()
  File "D:\Task Management System Final code\.venv\Lib\site-packages\pymysql\connections.py", line 1199, in read
    first_packet = self.connection._read_packet()
                   ^^^^^^^^^^^^^^^^^^^^^^^^^^^^^^
  File "D:\Task Management System Final code\.venv\Lib\site-packages\pymysql\connections.py", line 775, in _read_packet
    packet.raise_for_error()
  File "D:\Task Management System Final code\.venv\Lib\site-packages\pymysql\protocol.py", line 219, in raise_for_error
    err.raise_mysql_exception(self._data)
  File "D:\Task Management System Final code\.venv\Lib\site-packages\pymysql\err.py", line 150, in raise_mysql_exception
    raise errorclass(errno, errval)
pymysql.err.DataError: (1265, "Data truncated for column 'previous_status' at row 1")

The above exception was the direct cause of the following exception:

Traceback (most recent call last):
  File "D:\Task Management System Final code\Checklist\checklist_status.py", line 97, in update_Status
    update_parent_task_status(parent_task_id, db, Current_user)
  File "D:\Task Management System Final code\Checklist\functions.py", line 64, in update_parent_task_status
    db.flush()
  File "D:\Task Management System Final code\.venv\Lib\site-packages\sqlalchemy\orm\session.py", line 4353, in flush
    self._flush(objects)
  File "D:\Task Management System Final code\.venv\Lib\site-packages\sqlalchemy\orm\session.py", line 4488, in _flush
    with util.safe_reraise():
         ^^^^^^^^^^^^^^^^^^^
  File "D:\Task Management System Final code\.venv\Lib\site-packages\sqlalchemy\util\langhelpers.py", line 146, in __exit__
    raise exc_value.with_traceback(exc_tb)
  File "D:\Task Management System Final code\.venv\Lib\site-packages\sqlalchemy\orm\session.py", line 4449, in _flush
    flush_context.execute()
  File "D:\Task Management System Final code\.venv\Lib\site-packages\sqlalchemy\orm\unitofwork.py", line 466, in execute
    rec.execute(self)
  File "D:\Task Management System Final code\.venv\Lib\site-packages\sqlalchemy\orm\unitofwork.py", line 642, in execute
    util.preloaded.orm_persistence.save_obj(
  File "D:\Task Management System Final code\.venv\Lib\site-packages\sqlalchemy\orm\persistence.py", line 85, in save_obj
    _emit_update_statements(
  File "D:\Task Management System Final code\.venv\Lib\site-packages\sqlalchemy\orm\persistence.py", line 912, in _emit_update_statements
    c = connection.execute(
        ^^^^^^^^^^^^^^^^^^^
  File "D:\Task Management System Final code\.venv\Lib\site-packages\sqlalchemy\engine\base.py", line 1416, in execute
    return meth(
           ^^^^^
  File "D:\Task Management System Final code\.venv\Lib\site-packages\sqlalchemy\sql\elements.py", line 523, in _execute_on_connection
    return connection._execute_clauseelement(
           ^^^^^^^^^^^^^^^^^^^^^^^^^^^^^^^^^^
  File "D:\Task Management System Final code\.venv\Lib\site-packages\sqlalchemy\engine\base.py", line 1638, in _execute_clauseelement
    ret = self._execute_context(
          ^^^^^^^^^^^^^^^^^^^^^^
  File "D:\Task Management System Final code\.venv\Lib\site-packages\sqlalchemy\engine\base.py", line 1843, in _execute_context
    return self._exec_single_context(
           ^^^^^^^^^^^^^^^^^^^^^^^^^^
  File "D:\Task Management System Final code\.venv\Lib\site-packages\sqlalchemy\engine\base.py", line 1983, in _exec_single_context
    self._handle_dbapi_exception(
  File "D:\Task Management System Final code\.venv\Lib\site-packages\sqlalchemy\engine\base.py", line 2352, in _handle_dbapi_exception
    raise sqlalchemy_exception.with_traceback(exc_info[2]) from e
  File "D:\Task Management System Final code\.venv\Lib\site-packages\sqlalchemy\engine\base.py", line 1964, in _exec_single_context
    self.dialect.do_execute(
  File "D:\Task Management System Final code\.venv\Lib\site-packages\sqlalchemy\engine\default.py", line 945, in do_execute
    cursor.execute(statement, parameters)
  File "D:\Task Management System Final code\.venv\Lib\site-packages\pymysql\cursors.py", line 153, in execute
    result = self._query(query)
             ^^^^^^^^^^^^^^^^^^
  File "D:\Task Management System Final code\.venv\Lib\site-packages\pymysql\cursors.py", line 322, in _query
    conn.query(q)
  File "D:\Task Management System Final code\.venv\Lib\site-packages\pymysql\connections.py", line 563, in query
    self._affected_rows = self._read_query_result(unbuffered=unbuffered)
                          ^^^^^^^^^^^^^^^^^^^^^^^^^^^^^^^^^^^^^^^^^^^^^^
  File "D:\Task Management System Final code\.venv\Lib\site-packages\pymysql\connections.py", line 825, in _read_query_result
    result.read()
  File "D:\Task Management System Final code\.venv\Lib\site-packages\pymysql\connections.py", line 1199, in read
    first_packet = self.connection._read_packet()
                   ^^^^^^^^^^^^^^^^^^^^^^^^^^^^^^
  File "D:\Task Management System Final code\.venv\Lib\site-packages\pymysql\connections.py", line 775, in _read_packet
    packet.raise_for_error()
  File "D:\Task Management System Final code\.venv\Lib\site-packages\pymysql\protocol.py", line 219, in raise_for_error
    err.raise_mysql_exception(self._data)
  File "D:\Task Management System Final code\.venv\Lib\site-packages\pymysql\err.py", line 150, in raise_mysql_exception
    raise errorclass(errno, errval)
sqlalchemy.exc.DataError: (pymysql.err.DataError) (1265, "Data truncated for column 'previous_status' at row 1")
[SQL: UPDATE tasks SET previous_status=%(previous_status)s, updated_at=CURRENT_TIMESTAMP WHERE tasks.task_id = %(tasks_task_id)s]
[parameters: {'previous_status': 'In_Progress', 'tasks_task_id': 1}]
(Background on this error at: https://sqlalche.me/e/20/9h9h)
Traceback (most recent call last):
  File "D:\Task Management System Final code\.venv\Lib\site-packages\sqlalchemy\engine\base.py", line 1964, in _exec_single_context
    self.dialect.do_execute(
  File "D:\Task Management System Final code\.venv\Lib\site-packages\sqlalchemy\engine\default.py", line 945, in do_execute
    cursor.execute(statement, parameters)
  File "D:\Task Management System Final code\.venv\Lib\site-packages\pymysql\cursors.py", line 153, in execute
    result = self._query(query)
             ^^^^^^^^^^^^^^^^^^
  File "D:\Task Management System Final code\.venv\Lib\site-packages\pymysql\cursors.py", line 322, in _query
    conn.query(q)
  File "D:\Task Management System Final code\.venv\Lib\site-packages\pymysql\connections.py", line 563, in query
    self._affected_rows = self._read_query_result(unbuffered=unbuffered)
                          ^^^^^^^^^^^^^^^^^^^^^^^^^^^^^^^^^^^^^^^^^^^^^^
  File "D:\Task Management System Final code\.venv\Lib\site-packages\pymysql\connections.py", line 825, in _read_query_result
    result.read()
  File "D:\Task Management System Final code\.venv\Lib\site-packages\pymysql\connections.py", line 1199, in read
    first_packet = self.connection._read_packet()
                   ^^^^^^^^^^^^^^^^^^^^^^^^^^^^^^
  File "D:\Task Management System Final code\.venv\Lib\site-packages\pymysql\connections.py", line 775, in _read_packet
    packet.raise_for_error()
  File "D:\Task Management System Final code\.venv\Lib\site-packages\pymysql\protocol.py", line 219, in raise_for_error
    err.raise_mysql_exception(self._data)
  File "D:\Task Management System Final code\.venv\Lib\site-packages\pymysql\err.py", line 150, in raise_mysql_exception
    raise errorclass(errno, errval)
pymysql.err.DataError: (1265, "Data truncated for column 'previous_status' at row 1")

The above exception was the direct cause of the following exception:

Traceback (most recent call last):
  File "D:\Task Management System Final code\Checklist\checklist_status.py", line 97, in update_Status
    update_parent_task_status(parent_task_id, db, Current_user)
  File "D:\Task Management System Final code\Checklist\functions.py", line 64, in update_parent_task_status
    db.flush()
  File "D:\Task Management System Final code\.venv\Lib\site-packages\sqlalchemy\orm\session.py", line 4353, in flush
    self._flush(objects)
  File "D:\Task Management System Final code\.venv\Lib\site-packages\sqlalchemy\orm\session.py", line 4488, in _flush
    with util.safe_reraise():
         ^^^^^^^^^^^^^^^^^^^
  File "D:\Task Management System Final code\.venv\Lib\site-packages\sqlalchemy\util\langhelpers.py", line 146, in __exit__
    raise exc_value.with_traceback(exc_tb)
  File "D:\Task Management System Final code\.venv\Lib\site-packages\sqlalchemy\orm\session.py", line 4449, in _flush
    flush_context.execute()
  File "D:\Task Management System Final code\.venv\Lib\site-packages\sqlalchemy\orm\unitofwork.py", line 466, in execute
    rec.execute(self)
  File "D:\Task Management System Final code\.venv\Lib\site-packages\sqlalchemy\orm\unitofwork.py", line 642, in execute
    util.preloaded.orm_persistence.save_obj(
  File "D:\Task Management System Final code\.venv\Lib\site-packages\sqlalchemy\orm\persistence.py", line 85, in save_obj
    _emit_update_statements(
  File "D:\Task Management System Final code\.venv\Lib\site-packages\sqlalchemy\orm\persistence.py", line 912, in _emit_update_statements
    c = connection.execute(
        ^^^^^^^^^^^^^^^^^^^
  File "D:\Task Management System Final code\.venv\Lib\site-packages\sqlalchemy\engine\base.py", line 1416, in execute
    return meth(
           ^^^^^
  File "D:\Task Management System Final code\.venv\Lib\site-packages\sqlalchemy\sql\elements.py", line 523, in _execute_on_connection
    return connection._execute_clauseelement(
           ^^^^^^^^^^^^^^^^^^^^^^^^^^^^^^^^^^
  File "D:\Task Management System Final code\.venv\Lib\site-packages\sqlalchemy\engine\base.py", line 1638, in _execute_clauseelement
    ret = self._execute_context(
          ^^^^^^^^^^^^^^^^^^^^^^
  File "D:\Task Management System Final code\.venv\Lib\site-packages\sqlalchemy\engine\base.py", line 1843, in _execute_context
    return self._exec_single_context(
           ^^^^^^^^^^^^^^^^^^^^^^^^^^
  File "D:\Task Management System Final code\.venv\Lib\site-packages\sqlalchemy\engine\base.py", line 1983, in _exec_single_context
    self._handle_dbapi_exception(
  File "D:\Task Management System Final code\.venv\Lib\site-packages\sqlalchemy\engine\base.py", line 2352, in _handle_dbapi_exception
    raise sqlalchemy_exception.with_traceback(exc_info[2]) from e
  File "D:\Task Management System Final code\.venv\Lib\site-packages\sqlalchemy\engine\base.py", line 1964, in _exec_single_context
    self.dialect.do_execute(
  File "D:\Task Management System Final code\.venv\Lib\site-packages\sqlalchemy\engine\default.py", line 945, in do_execute
    cursor.execute(statement, parameters)
  File "D:\Task Management System Final code\.venv\Lib\site-packages\pymysql\cursors.py", line 153, in execute
    result = self._query(query)
             ^^^^^^^^^^^^^^^^^^
  File "D:\Task Management System Final code\.venv\Lib\site-packages\pymysql\cursors.py", line 322, in _query
    conn.query(q)
  File "D:\Task Management System Final code\.venv\Lib\site-packages\pymysql\connections.py", line 563, in query
    self._affected_rows = self._read_query_result(unbuffered=unbuffered)
                          ^^^^^^^^^^^^^^^^^^^^^^^^^^^^^^^^^^^^^^^^^^^^^^
  File "D:\Task Management System Final code\.venv\Lib\site-packages\pymysql\connections.py", line 825, in _read_query_result
    result.read()
  File "D:\Task Management System Final code\.venv\Lib\site-packages\pymysql\connections.py", line 1199, in read
    first_packet = self.connection._read_packet()
                   ^^^^^^^^^^^^^^^^^^^^^^^^^^^^^^
  File "D:\Task Management System Final code\.venv\Lib\site-packages\pymysql\connections.py", line 775, in _read_packet
    packet.raise_for_error()
  File "D:\Task Management System Final code\.venv\Lib\site-packages\pymysql\protocol.py", line 219, in raise_for_error
    err.raise_mysql_exception(self._data)
  File "D:\Task Management System Final code\.venv\Lib\site-packages\pymysql\err.py", line 150, in raise_mysql_exception
    raise errorclass(errno, errval)
sqlalchemy.exc.DataError: (pymysql.err.DataError) (1265, "Data truncated for column 'previous_status' at row 1")
[SQL: UPDATE tasks SET previous_status=%(previous_status)s, updated_at=CURRENT_TIMESTAMP WHERE tasks.task_id = %(tasks_task_id)s]
[parameters: {'previous_status': 'In_Progress', 'tasks_task_id': 1}]
(Background on this error at: https://sqlalche.me/e/20/9h9h)
Traceback (most recent call last):
  File "D:\Task Management System Final code\.venv\Lib\site-packages\sqlalchemy\engine\base.py", line 1964, in _exec_single_context
    self.dialect.do_execute(
  File "D:\Task Management System Final code\.venv\Lib\site-packages\sqlalchemy\engine\default.py", line 945, in do_execute
    cursor.execute(statement, parameters)
  File "D:\Task Management System Final code\.venv\Lib\site-packages\pymysql\cursors.py", line 153, in execute
    result = self._query(query)
             ^^^^^^^^^^^^^^^^^^
  File "D:\Task Management System Final code\.venv\Lib\site-packages\pymysql\cursors.py", line 322, in _query
    conn.query(q)
  File "D:\Task Management System Final code\.venv\Lib\site-packages\pymysql\connections.py", line 563, in query
    self._affected_rows = self._read_query_result(unbuffered=unbuffered)
                          ^^^^^^^^^^^^^^^^^^^^^^^^^^^^^^^^^^^^^^^^^^^^^^
  File "D:\Task Management System Final code\.venv\Lib\site-packages\pymysql\connections.py", line 825, in _read_query_result
    result.read()
  File "D:\Task Management System Final code\.venv\Lib\site-packages\pymysql\connections.py", line 1199, in read
    first_packet = self.connection._read_packet()
                   ^^^^^^^^^^^^^^^^^^^^^^^^^^^^^^
  File "D:\Task Management System Final code\.venv\Lib\site-packages\pymysql\connections.py", line 775, in _read_packet
    packet.raise_for_error()
  File "D:\Task Management System Final code\.venv\Lib\site-packages\pymysql\protocol.py", line 219, in raise_for_error
    err.raise_mysql_exception(self._data)
  File "D:\Task Management System Final code\.venv\Lib\site-packages\pymysql\err.py", line 150, in raise_mysql_exception
    raise errorclass(errno, errval)
pymysql.err.DataError: (1265, "Data truncated for column 'previous_status' at row 1")

The above exception was the direct cause of the following exception:

Traceback (most recent call last):
  File "D:\Task Management System Final code\Checklist\checklist_status.py", line 97, in update_Status
    update_parent_task_status(parent_task_id, db, Current_user)
  File "D:\Task Management System Final code\Checklist\functions.py", line 64, in update_parent_task_status
    db.flush()
  File "D:\Task Management System Final code\.venv\Lib\site-packages\sqlalchemy\orm\session.py", line 4353, in flush
    self._flush(objects)
  File "D:\Task Management System Final code\.venv\Lib\site-packages\sqlalchemy\orm\session.py", line 4488, in _flush
    with util.safe_reraise():
         ^^^^^^^^^^^^^^^^^^^
  File "D:\Task Management System Final code\.venv\Lib\site-packages\sqlalchemy\util\langhelpers.py", line 146, in __exit__
    raise exc_value.with_traceback(exc_tb)
  File "D:\Task Management System Final code\.venv\Lib\site-packages\sqlalchemy\orm\session.py", line 4449, in _flush
    flush_context.execute()
  File "D:\Task Management System Final code\.venv\Lib\site-packages\sqlalchemy\orm\unitofwork.py", line 466, in execute
    rec.execute(self)
  File "D:\Task Management System Final code\.venv\Lib\site-packages\sqlalchemy\orm\unitofwork.py", line 642, in execute
    util.preloaded.orm_persistence.save_obj(
  File "D:\Task Management System Final code\.venv\Lib\site-packages\sqlalchemy\orm\persistence.py", line 85, in save_obj
    _emit_update_statements(
  File "D:\Task Management System Final code\.venv\Lib\site-packages\sqlalchemy\orm\persistence.py", line 912, in _emit_update_statements
    c = connection.execute(
        ^^^^^^^^^^^^^^^^^^^
  File "D:\Task Management System Final code\.venv\Lib\site-packages\sqlalchemy\engine\base.py", line 1416, in execute
    return meth(
           ^^^^^
  File "D:\Task Management System Final code\.venv\Lib\site-packages\sqlalchemy\sql\elements.py", line 523, in _execute_on_connection
    return connection._execute_clauseelement(
           ^^^^^^^^^^^^^^^^^^^^^^^^^^^^^^^^^^
  File "D:\Task Management System Final code\.venv\Lib\site-packages\sqlalchemy\engine\base.py", line 1638, in _execute_clauseelement
    ret = self._execute_context(
          ^^^^^^^^^^^^^^^^^^^^^^
  File "D:\Task Management System Final code\.venv\Lib\site-packages\sqlalchemy\engine\base.py", line 1843, in _execute_context
    return self._exec_single_context(
           ^^^^^^^^^^^^^^^^^^^^^^^^^^
  File "D:\Task Management System Final code\.venv\Lib\site-packages\sqlalchemy\engine\base.py", line 1983, in _exec_single_context
    self._handle_dbapi_exception(
  File "D:\Task Management System Final code\.venv\Lib\site-packages\sqlalchemy\engine\base.py", line 2352, in _handle_dbapi_exception
    raise sqlalchemy_exception.with_traceback(exc_info[2]) from e
  File "D:\Task Management System Final code\.venv\Lib\site-packages\sqlalchemy\engine\base.py", line 1964, in _exec_single_context
    self.dialect.do_execute(
  File "D:\Task Management System Final code\.venv\Lib\site-packages\sqlalchemy\engine\default.py", line 945, in do_execute
    cursor.execute(statement, parameters)
  File "D:\Task Management System Final code\.venv\Lib\site-packages\pymysql\cursors.py", line 153, in execute
    result = self._query(query)
             ^^^^^^^^^^^^^^^^^^
  File "D:\Task Management System Final code\.venv\Lib\site-packages\pymysql\cursors.py", line 322, in _query
    conn.query(q)
  File "D:\Task Management System Final code\.venv\Lib\site-packages\pymysql\connections.py", line 563, in query
    self._affected_rows = self._read_query_result(unbuffered=unbuffered)
                          ^^^^^^^^^^^^^^^^^^^^^^^^^^^^^^^^^^^^^^^^^^^^^^
  File "D:\Task Management System Final code\.venv\Lib\site-packages\pymysql\connections.py", line 825, in _read_query_result
    result.read()
  File "D:\Task Management System Final code\.venv\Lib\site-packages\pymysql\connections.py", line 1199, in read
    first_packet = self.connection._read_packet()
                   ^^^^^^^^^^^^^^^^^^^^^^^^^^^^^^
  File "D:\Task Management System Final code\.venv\Lib\site-packages\pymysql\connections.py", line 775, in _read_packet
    packet.raise_for_error()
  File "D:\Task Management System Final code\.venv\Lib\site-packages\pymysql\protocol.py", line 219, in raise_for_error
    err.raise_mysql_exception(self._data)
  File "D:\Task Management System Final code\.venv\Lib\site-packages\pymysql\err.py", line 150, in raise_mysql_exception
    raise errorclass(errno, errval)
sqlalchemy.exc.DataError: (pymysql.err.DataError) (1265, "Data truncated for column 'previous_status' at row 1")
[SQL: UPDATE tasks SET previous_status=%(previous_status)s, updated_at=CURRENT_TIMESTAMP WHERE tasks.task_id = %(tasks_task_id)s]
[parameters: {'previous_status': 'In_Progress', 'tasks_task_id': 1}]
(Background on this error at: https://sqlalche.me/e/20/9h9h)
Traceback (most recent call last):
  File "D:\Task Management System Final code\.venv\Lib\site-packages\sqlalchemy\engine\base.py", line 1964, in _exec_single_context
    self.dialect.do_execute(
  File "D:\Task Management System Final code\.venv\Lib\site-packages\sqlalchemy\engine\default.py", line 945, in do_execute
    cursor.execute(statement, parameters)
  File "D:\Task Management System Final code\.venv\Lib\site-packages\pymysql\cursors.py", line 153, in execute
    result = self._query(query)
             ^^^^^^^^^^^^^^^^^^
  File "D:\Task Management System Final code\.venv\Lib\site-packages\pymysql\cursors.py", line 322, in _query
    conn.query(q)
  File "D:\Task Management System Final code\.venv\Lib\site-packages\pymysql\connections.py", line 563, in query
    self._affected_rows = self._read_query_result(unbuffered=unbuffered)
                          ^^^^^^^^^^^^^^^^^^^^^^^^^^^^^^^^^^^^^^^^^^^^^^
  File "D:\Task Management System Final code\.venv\Lib\site-packages\pymysql\connections.py", line 825, in _read_query_result
    result.read()
  File "D:\Task Management System Final code\.venv\Lib\site-packages\pymysql\connections.py", line 1199, in read
    first_packet = self.connection._read_packet()
                   ^^^^^^^^^^^^^^^^^^^^^^^^^^^^^^
  File "D:\Task Management System Final code\.venv\Lib\site-packages\pymysql\connections.py", line 775, in _read_packet
    packet.raise_for_error()
  File "D:\Task Management System Final code\.venv\Lib\site-packages\pymysql\protocol.py", line 219, in raise_for_error
    err.raise_mysql_exception(self._data)
  File "D:\Task Management System Final code\.venv\Lib\site-packages\pymysql\err.py", line 150, in raise_mysql_exception
    raise errorclass(errno, errval)
pymysql.err.DataError: (1265, "Data truncated for column 'previous_status' at row 1")

The above exception was the direct cause of the following exception:

Traceback (most recent call last):
  File "D:\Task Management System Final code\Checklist\checklist_status.py", line 97, in update_Status
    update_parent_task_status(parent_task_id, db, Current_user)
  File "D:\Task Management System Final code\Checklist\functions.py", line 64, in update_parent_task_status
    db.flush()
  File "D:\Task Management System Final code\.venv\Lib\site-packages\sqlalchemy\orm\session.py", line 4353, in flush
    self._flush(objects)
  File "D:\Task Management System Final code\.venv\Lib\site-packages\sqlalchemy\orm\session.py", line 4488, in _flush
    with util.safe_reraise():
         ^^^^^^^^^^^^^^^^^^^
  File "D:\Task Management System Final code\.venv\Lib\site-packages\sqlalchemy\util\langhelpers.py", line 146, in __exit__
    raise exc_value.with_traceback(exc_tb)
  File "D:\Task Management System Final code\.venv\Lib\site-packages\sqlalchemy\orm\session.py", line 4449, in _flush
    flush_context.execute()
  File "D:\Task Management System Final code\.venv\Lib\site-packages\sqlalchemy\orm\unitofwork.py", line 466, in execute
    rec.execute(self)
  File "D:\Task Management System Final code\.venv\Lib\site-packages\sqlalchemy\orm\unitofwork.py", line 642, in execute
    util.preloaded.orm_persistence.save_obj(
  File "D:\Task Management System Final code\.venv\Lib\site-packages\sqlalchemy\orm\persistence.py", line 85, in save_obj
    _emit_update_statements(
  File "D:\Task Management System Final code\.venv\Lib\site-packages\sqlalchemy\orm\persistence.py", line 912, in _emit_update_statements
    c = connection.execute(
        ^^^^^^^^^^^^^^^^^^^
  File "D:\Task Management System Final code\.venv\Lib\site-packages\sqlalchemy\engine\base.py", line 1416, in execute
    return meth(
           ^^^^^
  File "D:\Task Management System Final code\.venv\Lib\site-packages\sqlalchemy\sql\elements.py", line 523, in _execute_on_connection
    return connection._execute_clauseelement(
           ^^^^^^^^^^^^^^^^^^^^^^^^^^^^^^^^^^
  File "D:\Task Management System Final code\.venv\Lib\site-packages\sqlalchemy\engine\base.py", line 1638, in _execute_clauseelement
    ret = self._execute_context(
          ^^^^^^^^^^^^^^^^^^^^^^
  File "D:\Task Management System Final code\.venv\Lib\site-packages\sqlalchemy\engine\base.py", line 1843, in _execute_context
    return self._exec_single_context(
           ^^^^^^^^^^^^^^^^^^^^^^^^^^
  File "D:\Task Management System Final code\.venv\Lib\site-packages\sqlalchemy\engine\base.py", line 1983, in _exec_single_context
    self._handle_dbapi_exception(
  File "D:\Task Management System Final code\.venv\Lib\site-packages\sqlalchemy\engine\base.py", line 2352, in _handle_dbapi_exception
    raise sqlalchemy_exception.with_traceback(exc_info[2]) from e
  File "D:\Task Management System Final code\.venv\Lib\site-packages\sqlalchemy\engine\base.py", line 1964, in _exec_single_context
    self.dialect.do_execute(
  File "D:\Task Management System Final code\.venv\Lib\site-packages\sqlalchemy\engine\default.py", line 945, in do_execute
    cursor.execute(statement, parameters)
  File "D:\Task Management System Final code\.venv\Lib\site-packages\pymysql\cursors.py", line 153, in execute
    result = self._query(query)
             ^^^^^^^^^^^^^^^^^^
  File "D:\Task Management System Final code\.venv\Lib\site-packages\pymysql\cursors.py", line 322, in _query
    conn.query(q)
  File "D:\Task Management System Final code\.venv\Lib\site-packages\pymysql\connections.py", line 563, in query
    self._affected_rows = self._read_query_result(unbuffered=unbuffered)
                          ^^^^^^^^^^^^^^^^^^^^^^^^^^^^^^^^^^^^^^^^^^^^^^
  File "D:\Task Management System Final code\.venv\Lib\site-packages\pymysql\connections.py", line 825, in _read_query_result
    result.read()
  File "D:\Task Management System Final code\.venv\Lib\site-packages\pymysql\connections.py", line 1199, in read
    first_packet = self.connection._read_packet()
                   ^^^^^^^^^^^^^^^^^^^^^^^^^^^^^^
  File "D:\Task Management System Final code\.venv\Lib\site-packages\pymysql\connections.py", line 775, in _read_packet
    packet.raise_for_error()
  File "D:\Task Management System Final code\.venv\Lib\site-packages\pymysql\protocol.py", line 219, in raise_for_error
    err.raise_mysql_exception(self._data)
  File "D:\Task Management System Final code\.venv\Lib\site-packages\pymysql\err.py", line 150, in raise_mysql_exception
    raise errorclass(errno, errval)
sqlalchemy.exc.DataError: (pymysql.err.DataError) (1265, "Data truncated for column 'previous_status' at row 1")
[SQL: UPDATE tasks SET previous_status=%(previous_status)s, updated_at=CURRENT_TIMESTAMP WHERE tasks.task_id = %(tasks_task_id)s]
[parameters: {'previous_status': 'In_Progress', 'tasks_task_id': 1}]
(Background on this error at: https://sqlalche.me/e/20/9h9h)
Traceback (most recent call last):
  File "D:\Task Management System Final code\.venv\Lib\site-packages\sqlalchemy\engine\base.py", line 1964, in _exec_single_context
    self.dialect.do_execute(
  File "D:\Task Management System Final code\.venv\Lib\site-packages\sqlalchemy\engine\default.py", line 945, in do_execute
    cursor.execute(statement, parameters)
  File "D:\Task Management System Final code\.venv\Lib\site-packages\pymysql\cursors.py", line 153, in execute
    result = self._query(query)
             ^^^^^^^^^^^^^^^^^^
  File "D:\Task Management System Final code\.venv\Lib\site-packages\pymysql\cursors.py", line 322, in _query
    conn.query(q)
  File "D:\Task Management System Final code\.venv\Lib\site-packages\pymysql\connections.py", line 563, in query
    self._affected_rows = self._read_query_result(unbuffered=unbuffered)
                          ^^^^^^^^^^^^^^^^^^^^^^^^^^^^^^^^^^^^^^^^^^^^^^
  File "D:\Task Management System Final code\.venv\Lib\site-packages\pymysql\connections.py", line 825, in _read_query_result
    result.read()
  File "D:\Task Management System Final code\.venv\Lib\site-packages\pymysql\connections.py", line 1199, in read
    first_packet = self.connection._read_packet()
                   ^^^^^^^^^^^^^^^^^^^^^^^^^^^^^^
  File "D:\Task Management System Final code\.venv\Lib\site-packages\pymysql\connections.py", line 775, in _read_packet
    packet.raise_for_error()
  File "D:\Task Management System Final code\.venv\Lib\site-packages\pymysql\protocol.py", line 219, in raise_for_error
    err.raise_mysql_exception(self._data)
  File "D:\Task Management System Final code\.venv\Lib\site-packages\pymysql\err.py", line 150, in raise_mysql_exception
    raise errorclass(errno, errval)
pymysql.err.DataError: (1265, "Data truncated for column 'previous_status' at row 1")

The above exception was the direct cause of the following exception:

Traceback (most recent call last):
  File "D:\Task Management System Final code\Checklist\checklist_status.py", line 97, in update_Status
    update_parent_task_status(parent_task_id, db, Current_user)
  File "D:\Task Management System Final code\Checklist\functions.py", line 64, in update_parent_task_status
    db.flush()
  File "D:\Task Management System Final code\.venv\Lib\site-packages\sqlalchemy\orm\session.py", line 4353, in flush
    self._flush(objects)
  File "D:\Task Management System Final code\.venv\Lib\site-packages\sqlalchemy\orm\session.py", line 4488, in _flush
    with util.safe_reraise():
         ^^^^^^^^^^^^^^^^^^^
  File "D:\Task Management System Final code\.venv\Lib\site-packages\sqlalchemy\util\langhelpers.py", line 146, in __exit__
    raise exc_value.with_traceback(exc_tb)
  File "D:\Task Management System Final code\.venv\Lib\site-packages\sqlalchemy\orm\session.py", line 4449, in _flush
    flush_context.execute()
  File "D:\Task Management System Final code\.venv\Lib\site-packages\sqlalchemy\orm\unitofwork.py", line 466, in execute
    rec.execute(self)
  File "D:\Task Management System Final code\.venv\Lib\site-packages\sqlalchemy\orm\unitofwork.py", line 642, in execute
    util.preloaded.orm_persistence.save_obj(
  File "D:\Task Management System Final code\.venv\Lib\site-packages\sqlalchemy\orm\persistence.py", line 85, in save_obj
    _emit_update_statements(
  File "D:\Task Management System Final code\.venv\Lib\site-packages\sqlalchemy\orm\persistence.py", line 912, in _emit_update_statements
    c = connection.execute(
        ^^^^^^^^^^^^^^^^^^^
  File "D:\Task Management System Final code\.venv\Lib\site-packages\sqlalchemy\engine\base.py", line 1416, in execute
    return meth(
           ^^^^^
  File "D:\Task Management System Final code\.venv\Lib\site-packages\sqlalchemy\sql\elements.py", line 523, in _execute_on_connection
    return connection._execute_clauseelement(
           ^^^^^^^^^^^^^^^^^^^^^^^^^^^^^^^^^^
  File "D:\Task Management System Final code\.venv\Lib\site-packages\sqlalchemy\engine\base.py", line 1638, in _execute_clauseelement
    ret = self._execute_context(
          ^^^^^^^^^^^^^^^^^^^^^^
  File "D:\Task Management System Final code\.venv\Lib\site-packages\sqlalchemy\engine\base.py", line 1843, in _execute_context
    return self._exec_single_context(
           ^^^^^^^^^^^^^^^^^^^^^^^^^^
  File "D:\Task Management System Final code\.venv\Lib\site-packages\sqlalchemy\engine\base.py", line 1983, in _exec_single_context
    self._handle_dbapi_exception(
  File "D:\Task Management System Final code\.venv\Lib\site-packages\sqlalchemy\engine\base.py", line 2352, in _handle_dbapi_exception
    raise sqlalchemy_exception.with_traceback(exc_info[2]) from e
  File "D:\Task Management System Final code\.venv\Lib\site-packages\sqlalchemy\engine\base.py", line 1964, in _exec_single_context
    self.dialect.do_execute(
  File "D:\Task Management System Final code\.venv\Lib\site-packages\sqlalchemy\engine\default.py", line 945, in do_execute
    cursor.execute(statement, parameters)
  File "D:\Task Management System Final code\.venv\Lib\site-packages\pymysql\cursors.py", line 153, in execute
    result = self._query(query)
             ^^^^^^^^^^^^^^^^^^
  File "D:\Task Management System Final code\.venv\Lib\site-packages\pymysql\cursors.py", line 322, in _query
    conn.query(q)
  File "D:\Task Management System Final code\.venv\Lib\site-packages\pymysql\connections.py", line 563, in query
    self._affected_rows = self._read_query_result(unbuffered=unbuffered)
                          ^^^^^^^^^^^^^^^^^^^^^^^^^^^^^^^^^^^^^^^^^^^^^^
  File "D:\Task Management System Final code\.venv\Lib\site-packages\pymysql\connections.py", line 825, in _read_query_result
    result.read()
  File "D:\Task Management System Final code\.venv\Lib\site-packages\pymysql\connections.py", line 1199, in read
    first_packet = self.connection._read_packet()
                   ^^^^^^^^^^^^^^^^^^^^^^^^^^^^^^
  File "D:\Task Management System Final code\.venv\Lib\site-packages\pymysql\connections.py", line 775, in _read_packet
    packet.raise_for_error()
  File "D:\Task Management System Final code\.venv\Lib\site-packages\pymysql\protocol.py", line 219, in raise_for_error
    err.raise_mysql_exception(self._data)
  File "D:\Task Management System Final code\.venv\Lib\site-packages\pymysql\err.py", line 150, in raise_mysql_exception
    raise errorclass(errno, errval)
sqlalchemy.exc.DataError: (pymysql.err.DataError) (1265, "Data truncated for column 'previous_status' at row 1")
[SQL: UPDATE tasks SET previous_status=%(previous_status)s, updated_at=CURRENT_TIMESTAMP WHERE tasks.task_id = %(tasks_task_id)s]
[parameters: {'previous_status': 'In_Progress', 'tasks_task_id': 1}]
(Background on this error at: https://sqlalche.me/e/20/9h9h)
Traceback (most recent call last):
  File "D:\Task Management System Final code\.venv\Lib\site-packages\sqlalchemy\engine\base.py", line 1964, in _exec_single_context
    self.dialect.do_execute(
  File "D:\Task Management System Final code\.venv\Lib\site-packages\sqlalchemy\engine\default.py", line 945, in do_execute
    cursor.execute(statement, parameters)
  File "D:\Task Management System Final code\.venv\Lib\site-packages\pymysql\cursors.py", line 153, in execute
    result = self._query(query)
             ^^^^^^^^^^^^^^^^^^
  File "D:\Task Management System Final code\.venv\Lib\site-packages\pymysql\cursors.py", line 322, in _query
    conn.query(q)
  File "D:\Task Management System Final code\.venv\Lib\site-packages\pymysql\connections.py", line 563, in query
    self._affected_rows = self._read_query_result(unbuffered=unbuffered)
                          ^^^^^^^^^^^^^^^^^^^^^^^^^^^^^^^^^^^^^^^^^^^^^^
  File "D:\Task Management System Final code\.venv\Lib\site-packages\pymysql\connections.py", line 825, in _read_query_result
    result.read()
  File "D:\Task Management System Final code\.venv\Lib\site-packages\pymysql\connections.py", line 1199, in read
    first_packet = self.connection._read_packet()
                   ^^^^^^^^^^^^^^^^^^^^^^^^^^^^^^
  File "D:\Task Management System Final code\.venv\Lib\site-packages\pymysql\connections.py", line 775, in _read_packet
    packet.raise_for_error()
  File "D:\Task Management System Final code\.venv\Lib\site-packages\pymysql\protocol.py", line 219, in raise_for_error
    err.raise_mysql_exception(self._data)
  File "D:\Task Management System Final code\.venv\Lib\site-packages\pymysql\err.py", line 150, in raise_mysql_exception
    raise errorclass(errno, errval)
pymysql.err.DataError: (1265, "Data truncated for column 'previous_status' at row 1")

The above exception was the direct cause of the following exception:

Traceback (most recent call last):
  File "D:\Task Management System Final code\Checklist\checklist_status.py", line 97, in update_Status
    update_parent_task_status(parent_task_id, db, Current_user)
  File "D:\Task Management System Final code\Checklist\functions.py", line 64, in update_parent_task_status
    db.flush()
  File "D:\Task Management System Final code\.venv\Lib\site-packages\sqlalchemy\orm\session.py", line 4353, in flush
    self._flush(objects)
  File "D:\Task Management System Final code\.venv\Lib\site-packages\sqlalchemy\orm\session.py", line 4488, in _flush
    with util.safe_reraise():
         ^^^^^^^^^^^^^^^^^^^
  File "D:\Task Management System Final code\.venv\Lib\site-packages\sqlalchemy\util\langhelpers.py", line 146, in __exit__
    raise exc_value.with_traceback(exc_tb)
  File "D:\Task Management System Final code\.venv\Lib\site-packages\sqlalchemy\orm\session.py", line 4449, in _flush
    flush_context.execute()
  File "D:\Task Management System Final code\.venv\Lib\site-packages\sqlalchemy\orm\unitofwork.py", line 466, in execute
    rec.execute(self)
  File "D:\Task Management System Final code\.venv\Lib\site-packages\sqlalchemy\orm\unitofwork.py", line 642, in execute
    util.preloaded.orm_persistence.save_obj(
  File "D:\Task Management System Final code\.venv\Lib\site-packages\sqlalchemy\orm\persistence.py", line 85, in save_obj
    _emit_update_statements(
  File "D:\Task Management System Final code\.venv\Lib\site-packages\sqlalchemy\orm\persistence.py", line 912, in _emit_update_statements
    c = connection.execute(
        ^^^^^^^^^^^^^^^^^^^
  File "D:\Task Management System Final code\.venv\Lib\site-packages\sqlalchemy\engine\base.py", line 1416, in execute
    return meth(
           ^^^^^
  File "D:\Task Management System Final code\.venv\Lib\site-packages\sqlalchemy\sql\elements.py", line 523, in _execute_on_connection
    return connection._execute_clauseelement(
           ^^^^^^^^^^^^^^^^^^^^^^^^^^^^^^^^^^
  File "D:\Task Management System Final code\.venv\Lib\site-packages\sqlalchemy\engine\base.py", line 1638, in _execute_clauseelement
    ret = self._execute_context(
          ^^^^^^^^^^^^^^^^^^^^^^
  File "D:\Task Management System Final code\.venv\Lib\site-packages\sqlalchemy\engine\base.py", line 1843, in _execute_context
    return self._exec_single_context(
           ^^^^^^^^^^^^^^^^^^^^^^^^^^
  File "D:\Task Management System Final code\.venv\Lib\site-packages\sqlalchemy\engine\base.py", line 1983, in _exec_single_context
    self._handle_dbapi_exception(
  File "D:\Task Management System Final code\.venv\Lib\site-packages\sqlalchemy\engine\base.py", line 2352, in _handle_dbapi_exception
    raise sqlalchemy_exception.with_traceback(exc_info[2]) from e
  File "D:\Task Management System Final code\.venv\Lib\site-packages\sqlalchemy\engine\base.py", line 1964, in _exec_single_context
    self.dialect.do_execute(
  File "D:\Task Management System Final code\.venv\Lib\site-packages\sqlalchemy\engine\default.py", line 945, in do_execute
    cursor.execute(statement, parameters)
  File "D:\Task Management System Final code\.venv\Lib\site-packages\pymysql\cursors.py", line 153, in execute
    result = self._query(query)
             ^^^^^^^^^^^^^^^^^^
  File "D:\Task Management System Final code\.venv\Lib\site-packages\pymysql\cursors.py", line 322, in _query
    conn.query(q)
  File "D:\Task Management System Final code\.venv\Lib\site-packages\pymysql\connections.py", line 563, in query
    self._affected_rows = self._read_query_result(unbuffered=unbuffered)
                          ^^^^^^^^^^^^^^^^^^^^^^^^^^^^^^^^^^^^^^^^^^^^^^
  File "D:\Task Management System Final code\.venv\Lib\site-packages\pymysql\connections.py", line 825, in _read_query_result
    result.read()
  File "D:\Task Management System Final code\.venv\Lib\site-packages\pymysql\connections.py", line 1199, in read
    first_packet = self.connection._read_packet()
                   ^^^^^^^^^^^^^^^^^^^^^^^^^^^^^^
  File "D:\Task Management System Final code\.venv\Lib\site-packages\pymysql\connections.py", line 775, in _read_packet
    packet.raise_for_error()
  File "D:\Task Management System Final code\.venv\Lib\site-packages\pymysql\protocol.py", line 219, in raise_for_error
    err.raise_mysql_exception(self._data)
  File "D:\Task Management System Final code\.venv\Lib\site-packages\pymysql\err.py", line 150, in raise_mysql_exception
    raise errorclass(errno, errval)
sqlalchemy.exc.DataError: (pymysql.err.DataError) (1265, "Data truncated for column 'previous_status' at row 1")
[SQL: UPDATE tasks SET status=%(status)s, previous_status=%(previous_status)s, updated_at=CURRENT_TIMESTAMP WHERE tasks.task_id = %(tasks_task_id)s]
[parameters: {'status': 'In_Progress', 'previous_status': 'In_Progress', 'tasks_task_id': 1}]
(Background on this error at: https://sqlalche.me/e/20/9h9h)
Traceback (most recent call last):
  File "D:\Task Management System Final code\Checklist\checklist_status.py", line 138, in update_Status
    log_task_field_change(db, child_task.task_id, "status", old_status, child_task.previous_status, 2)
                                                            ^^^^^^^^^^
UnboundLocalError: cannot access local variable 'old_status' where it is not associated with a value
Traceback (most recent call last):
  File "D:\Task Management System Final code\Checklist\checklist_status.py", line 138, in update_Status
    log_task_field_change(db, child_task.task_id, "status", old_status, child_task.previous_status, 2)
                                                            ^^^^^^^^^^
UnboundLocalError: cannot access local variable 'old_status' where it is not associated with a value
Traceback (most recent call last):
  File "D:\Task Management System Final code\Checklist\checklist_status.py", line 138, in update_Status
    log_task_field_change(db, child_task.task_id, "status", old_status, child_task.previous_status, 2)
                                                            ^^^^^^^^^^
UnboundLocalError: cannot access local variable 'old_status' where it is not associated with a value
2025-05-08 16:19:58,686 - mark_checklist_complete - INFO - POST /mark_checklist_complete called by user_id=5
2025-05-08 16:19:58,686 - mark_checklist_complete - INFO - Checklist 1 found, current status: True
2025-05-08 16:19:58,703 - mark_checklist_complete - WARNING - User 5 has no access to parent task 1
2025-05-08 16:20:27,232 - mark_checklist_complete - INFO - POST /mark_checklist_complete called by user_id=5
2025-05-08 16:20:27,244 - mark_checklist_complete - INFO - Checklist 29 found, current status: False
2025-05-08 16:20:27,248 - mark_checklist_complete - INFO - Checklist is linked to parent_task_id=19, task_type=TaskType.Normal
2025-05-08 16:20:27,263 - mark_checklist_complete - INFO - Checklist 29 marked as completed
2025-05-08 16:20:27,313 - mark_checklist_complete - INFO - Checklist status updated and committed successfully
2025-05-08 16:20:48,075 - mark_checklist_complete - INFO - POST /mark_checklist_complete called by user_id=5
2025-05-08 16:20:48,075 - mark_checklist_complete - INFO - Checklist 29 found, current status: True
2025-05-08 16:20:48,091 - mark_checklist_complete - INFO - Checklist is linked to parent_task_id=19, task_type=TaskType.Normal
2025-05-08 16:20:48,091 - mark_checklist_complete - INFO - Checklist 29 marked as incomplete
2025-05-08 16:20:48,126 - mark_checklist_complete - INFO - Checklist status updated and committed successfully
2025-05-10 10:06:39,647 - mark_checklist_complete - INFO - POST /mark_checklist_complete called by user_id=5
2025-05-10 10:06:39,647 - mark_checklist_complete - INFO - Checklist 31 found, current status: False
2025-05-10 10:06:39,663 - mark_checklist_complete - INFO - Checklist is linked to parent_task_id=22, task_type=TaskType.Normal
2025-05-10 10:06:39,685 - mark_checklist_complete - INFO - Checklist 31 marked as completed
2025-05-10 10:06:39,780 - mark_checklist_complete - INFO - Checklist status updated and committed successfully
2025-05-10 10:06:44,284 - mark_checklist_complete - INFO - POST /mark_checklist_complete called by user_id=5
2025-05-10 10:06:44,301 - mark_checklist_complete - INFO - Checklist 32 found, current status: False
2025-05-10 10:06:44,306 - mark_checklist_complete - INFO - Checklist is linked to parent_task_id=22, task_type=TaskType.Normal
2025-05-10 10:06:44,306 - mark_checklist_complete - INFO - Checklist 32 marked as completed
2025-05-10 10:06:44,334 - mark_checklist_complete - INFO - Checklist status updated and committed successfully
2025-05-10 10:06:49,238 - mark_checklist_complete - INFO - POST /mark_checklist_complete called by user_id=5
2025-05-10 10:06:49,238 - mark_checklist_complete - INFO - Checklist 33 found, current status: False
2025-05-10 10:06:49,260 - mark_checklist_complete - INFO - Checklist is linked to parent_task_id=22, task_type=TaskType.Normal
2025-05-10 10:06:49,262 - mark_checklist_complete - INFO - Checklist 33 marked as completed
2025-05-10 10:06:49,288 - mark_checklist_complete - INFO - Checklist status updated and committed successfully
2025-05-10 10:06:54,425 - mark_checklist_complete - INFO - POST /mark_checklist_complete called by user_id=5
2025-05-10 10:06:54,425 - mark_checklist_complete - WARNING - Checklist 34 not found or deleted
2025-05-10 10:07:00,801 - mark_checklist_complete - INFO - POST /mark_checklist_complete called by user_id=5
2025-05-10 10:07:00,814 - mark_checklist_complete - INFO - Checklist 30 found, current status: False
2025-05-10 10:07:00,814 - mark_checklist_complete - INFO - Checklist is linked to parent_task_id=22, task_type=TaskType.Normal
2025-05-10 10:07:00,814 - mark_checklist_complete - INFO - Checklist 30 marked as completed
2025-05-10 10:07:00,863 - mark_checklist_complete - INFO - Checklist status updated and committed successfully
2025-05-10 10:08:20,403 - mark_checklist_complete - INFO - POST /mark_checklist_complete called by user_id=5
2025-05-10 10:08:20,403 - mark_checklist_complete - INFO - Checklist 36 found, current status: False
2025-05-10 10:08:20,414 - mark_checklist_complete - INFO - Checklist is linked to parent_task_id=22, task_type=TaskType.Normal
2025-05-10 10:08:20,417 - mark_checklist_complete - WARNING - Checklist 36 has subtasks and cannot be directly updated
2025-05-10 10:08:27,510 - mark_checklist_complete - INFO - POST /mark_checklist_complete called by user_id=5
2025-05-10 10:08:27,510 - mark_checklist_complete - INFO - Checklist 37 found, current status: False
2025-05-10 10:08:27,515 - mark_checklist_complete - INFO - Checklist is linked to parent_task_id=24, task_type=TaskType.Normal
2025-05-10 10:08:27,518 - mark_checklist_complete - INFO - Checklist 37 marked as completed
2025-05-10 10:08:27,531 - mark_checklist_complete - INFO - Checklist status updated and committed successfully
2025-05-10 10:11:46,346 - mark_checklist_complete - INFO - POST /mark_checklist_complete called by user_id=5
2025-05-10 10:11:46,350 - mark_checklist_complete - INFO - Checklist 40 found, current status: False
2025-05-10 10:11:46,351 - mark_checklist_complete - INFO - Checklist is linked to parent_task_id=24, task_type=TaskType.Normal
2025-05-10 10:11:46,366 - mark_checklist_complete - INFO - Checklist 40 marked as completed
2025-05-10 10:11:46,384 - mark_checklist_complete - INFO - Checklist status updated and committed successfully
2025-05-10 10:11:50,890 - mark_checklist_complete - INFO - POST /mark_checklist_complete called by user_id=5
2025-05-10 10:11:50,890 - mark_checklist_complete - INFO - Checklist 41 found, current status: False
2025-05-10 10:11:50,890 - mark_checklist_complete - INFO - Checklist is linked to parent_task_id=24, task_type=TaskType.Normal
2025-05-10 10:11:50,890 - mark_checklist_complete - INFO - Checklist 41 marked as completed
2025-05-10 10:11:50,924 - mark_checklist_complete - INFO - Checklist status updated and committed successfully
2025-05-10 10:11:53,991 - mark_checklist_complete - INFO - POST /mark_checklist_complete called by user_id=5
2025-05-10 10:11:53,991 - mark_checklist_complete - INFO - Checklist 42 found, current status: False
2025-05-10 10:11:54,005 - mark_checklist_complete - INFO - Checklist is linked to parent_task_id=24, task_type=TaskType.Normal
2025-05-10 10:11:54,007 - mark_checklist_complete - INFO - Checklist 42 marked as completed
2025-05-10 10:11:54,044 - mark_checklist_complete - INFO - Checklist status updated and committed successfully
2025-05-10 10:12:44,432 - mark_checklist_complete - INFO - POST /mark_checklist_complete called by user_id=5
2025-05-10 10:12:44,449 - mark_checklist_complete - INFO - Checklist 34 found, current status: False
2025-05-10 10:12:44,454 - mark_checklist_complete - INFO - Checklist is linked to parent_task_id=22, task_type=TaskType.Normal
2025-05-10 10:12:44,454 - mark_checklist_complete - INFO - Checklist 34 marked as completed
2025-05-10 10:12:44,482 - mark_checklist_complete - INFO - Checklist status updated and committed successfully
2025-05-10 10:12:50,138 - mark_checklist_complete - INFO - POST /mark_checklist_complete called by user_id=5
2025-05-10 10:12:50,138 - mark_checklist_complete - INFO - Checklist 35 found, current status: False
2025-05-10 10:12:50,154 - mark_checklist_complete - INFO - Checklist is linked to parent_task_id=22, task_type=TaskType.Normal
2025-05-10 10:12:50,154 - mark_checklist_complete - INFO - Checklist 35 marked as completed
2025-05-10 10:12:50,187 - mark_checklist_complete - INFO - Checklist status updated and committed successfully
2025-05-10 10:13:03,747 - mark_checklist_complete - INFO - POST /mark_checklist_complete called by user_id=5
2025-05-10 10:13:03,748 - mark_checklist_complete - INFO - Checklist 35 found, current status: True
2025-05-10 10:13:03,748 - mark_checklist_complete - INFO - Checklist is linked to parent_task_id=22, task_type=TaskType.Normal
2025-05-10 10:13:03,748 - mark_checklist_complete - INFO - Checklist 35 marked as incomplete
2025-05-10 10:13:03,783 - mark_checklist_complete - INFO - Checklist status updated and committed successfully
2025-05-10 10:14:31,321 - mark_checklist_complete - INFO - POST /mark_checklist_complete called by user_id=5
2025-05-10 10:14:31,321 - mark_checklist_complete - INFO - Checklist 35 found, current status: False
2025-05-10 10:14:31,337 - mark_checklist_complete - INFO - Checklist is linked to parent_task_id=22, task_type=TaskType.Normal
2025-05-10 10:14:31,339 - mark_checklist_complete - INFO - Checklist 35 marked as completed
2025-05-10 10:14:31,371 - mark_checklist_complete - INFO - Checklist status updated and committed successfully
2025-05-10 10:15:38,827 - mark_checklist_complete - INFO - POST /mark_checklist_complete called by user_id=5
2025-05-10 10:15:38,827 - mark_checklist_complete - INFO - Checklist 43 found, current status: False
2025-05-10 10:15:38,844 - mark_checklist_complete - INFO - Checklist is linked to parent_task_id=22, task_type=TaskType.Normal
2025-05-10 10:15:38,853 - mark_checklist_complete - INFO - Checklist 43 marked as completed
2025-05-10 10:15:38,893 - mark_checklist_complete - INFO - Checklist status updated and committed successfully
2025-05-10 10:25:31,292 - mark_checklist_complete - INFO - POST /mark_checklist_complete called by user_id=5
2025-05-10 10:25:31,299 - mark_checklist_complete - INFO - Checklist 48 found, current status: False
2025-05-10 10:25:31,307 - mark_checklist_complete - INFO - Checklist is linked to parent_task_id=34, task_type=TaskType.Normal
2025-05-10 10:25:31,316 - mark_checklist_complete - INFO - Checklist 48 marked as completed
2025-05-10 10:25:31,358 - mark_checklist_complete - INFO - Checklist status updated and committed successfully
2025-05-10 10:25:45,178 - mark_checklist_complete - INFO - POST /mark_checklist_complete called by user_id=5
2025-05-10 10:25:45,182 - mark_checklist_complete - INFO - Checklist 48 found, current status: True
2025-05-10 10:25:45,184 - mark_checklist_complete - INFO - Checklist is linked to parent_task_id=34, task_type=TaskType.Normal
2025-05-10 10:25:45,196 - mark_checklist_complete - INFO - Checklist 48 marked as incomplete
2025-05-10 10:25:45,249 - mark_checklist_complete - INFO - Checklist status updated and committed successfully
2025-05-10 10:25:55,337 - mark_checklist_complete - INFO - POST /mark_checklist_complete called by user_id=5
2025-05-10 10:25:55,337 - mark_checklist_complete - INFO - Checklist 48 found, current status: False
2025-05-10 10:25:55,353 - mark_checklist_complete - INFO - Checklist is linked to parent_task_id=34, task_type=TaskType.Normal
2025-05-10 10:25:55,353 - mark_checklist_complete - INFO - Checklist 48 marked as completed
2025-05-10 10:25:55,387 - mark_checklist_complete - INFO - Checklist status updated and committed successfully
2025-05-10 10:26:23,529 - mark_checklist_complete - INFO - POST /mark_checklist_complete called by user_id=5
2025-05-10 10:26:23,546 - mark_checklist_complete - INFO - Checklist 49 found, current status: False
2025-05-10 10:26:23,546 - mark_checklist_complete - INFO - Checklist is linked to parent_task_id=34, task_type=TaskType.Normal
2025-05-10 10:26:23,546 - mark_checklist_complete - INFO - Checklist 49 marked as completed
2025-05-10 10:26:23,577 - mark_checklist_complete - INFO - Checklist status updated and committed successfully
2025-05-10 10:26:30,286 - mark_checklist_complete - INFO - POST /mark_checklist_complete called by user_id=5
2025-05-10 10:26:30,290 - mark_checklist_complete - INFO - Checklist 49 found, current status: True
2025-05-10 10:26:30,296 - mark_checklist_complete - INFO - Checklist is linked to parent_task_id=34, task_type=TaskType.Normal
2025-05-10 10:26:30,299 - mark_checklist_complete - INFO - Checklist 49 marked as incomplete
2025-05-10 10:26:30,356 - mark_checklist_complete - INFO - Checklist status updated and committed successfully
2025-05-10 10:26:39,240 - mark_checklist_complete - INFO - POST /mark_checklist_complete called by user_id=5
2025-05-10 10:26:39,240 - mark_checklist_complete - INFO - Checklist 49 found, current status: False
2025-05-10 10:26:39,240 - mark_checklist_complete - INFO - Checklist is linked to parent_task_id=34, task_type=TaskType.Normal
2025-05-10 10:26:39,258 - mark_checklist_complete - INFO - Checklist 49 marked as completed
2025-05-10 10:26:39,291 - mark_checklist_complete - INFO - Checklist status updated and committed successfully
2025-05-10 10:41:54,282 - mark_checklist_complete - INFO - POST /mark_checklist_complete called by user_id=5
2025-05-10 10:41:54,297 - mark_checklist_complete - INFO - Checklist 50 found, current status: False
2025-05-10 10:41:54,306 - mark_checklist_complete - INFO - Checklist is linked to parent_task_id=36, task_type=TaskType.Normal
2025-05-10 10:41:54,314 - mark_checklist_complete - INFO - Checklist 50 marked as completed
2025-05-10 10:41:54,347 - mark_checklist_complete - INFO - Checklist status updated and committed successfully
2025-05-10 10:44:53,770 - mark_checklist_complete - INFO - POST /mark_checklist_complete called by user_id=5
2025-05-10 10:44:53,774 - mark_checklist_complete - INFO - Checklist 53 found, current status: False
2025-05-10 10:44:53,779 - mark_checklist_complete - INFO - Checklist is linked to parent_task_id=37, task_type=TaskType.Normal
2025-05-10 10:44:53,788 - mark_checklist_complete - INFO - Checklist 53 marked as completed
2025-05-10 10:44:53,830 - mark_checklist_complete - INFO - Checklist status updated and committed successfully
2025-05-10 10:50:02,519 - mark_checklist_complete - INFO - POST /mark_checklist_complete called by user_id=5
2025-05-10 10:50:02,519 - mark_checklist_complete - INFO - Checklist 54 found, current status: False
2025-05-10 10:50:02,559 - mark_checklist_complete - INFO - Checklist is linked to parent_task_id=37, task_type=TaskType.Normal
2025-05-10 10:50:02,576 - mark_checklist_complete - INFO - Checklist 54 marked as completed
2025-05-10 10:50:02,618 - mark_checklist_complete - INFO - Checklist status updated and committed successfully
2025-05-10 10:50:07,939 - mark_checklist_complete - INFO - POST /mark_checklist_complete called by user_id=5
2025-05-10 10:50:07,939 - mark_checklist_complete - INFO - Checklist 55 found, current status: False
2025-05-10 10:50:07,957 - mark_checklist_complete - INFO - Checklist is linked to parent_task_id=37, task_type=TaskType.Normal
2025-05-10 10:50:07,957 - mark_checklist_complete - INFO - Checklist 55 marked as completed
2025-05-10 10:50:07,989 - mark_checklist_complete - INFO - Checklist status updated and committed successfully
2025-05-10 10:50:13,611 - mark_checklist_complete - INFO - POST /mark_checklist_complete called by user_id=5
2025-05-10 10:50:13,611 - mark_checklist_complete - INFO - Checklist 56 found, current status: False
2025-05-10 10:50:13,611 - mark_checklist_complete - INFO - Checklist is linked to parent_task_id=37, task_type=TaskType.Normal
2025-05-10 10:50:13,629 - mark_checklist_complete - INFO - Checklist 56 marked as completed
2025-05-10 10:50:13,646 - mark_checklist_complete - INFO - Checklist status updated and committed successfully
2025-05-10 10:50:19,349 - mark_checklist_complete - INFO - POST /mark_checklist_complete called by user_id=5
2025-05-10 10:50:19,349 - mark_checklist_complete - INFO - Checklist 57 found, current status: False
2025-05-10 10:50:19,367 - mark_checklist_complete - INFO - Checklist is linked to parent_task_id=37, task_type=TaskType.Normal
2025-05-10 10:50:19,367 - mark_checklist_complete - INFO - Checklist 57 marked as completed
2025-05-10 10:50:19,415 - mark_checklist_complete - INFO - Checklist status updated and committed successfully
2025-05-16 17:20:55,201 - mark_checklist_complete - INFO - POST /mark_checklist_complete called by user_id=2
2025-05-16 17:20:55,203 - mark_checklist_complete - INFO - Checklist 5 found, current status: False
