2025-04-29 10:46:43,035 - send_for_review - INFO - POST /send_for_review called by user_id=1 for task_id=12
2025-04-29 10:46:43,058 - send_for_review - ERROR - Unexpected error while sending for review
Traceback (most recent call last):
  File "D:\Task Management System Final code\Tasks\Update_Task.py", line 228, in send_for_review
    status=TaskStatus.Pending.name,  # New review is pending initially
           ^^^^^^^^^^^^^^^^^^
AttributeError: type object 'TaskStatus' has no attribute 'Pending'
2025-04-29 10:47:17,451 - send_for_review - INFO - POST /send_for_review called by user_id=1 for task_id=12
2025-04-29 10:47:17,479 - send_for_review - INFO - Review task 13 created successfully
2025-04-29 10:47:24,666 - send_for_review - INFO - POST /send_for_review called by user_id=1 for task_id=13
2025-04-29 10:47:24,691 - send_for_review - INFO - Review task 14 created successfully
2025-04-29 10:47:27,567 - send_for_review - INFO - POST /send_for_review called by user_id=1 for task_id=13
2025-04-29 10:47:27,570 - send_for_review - ERROR - Unexpected error while sending for review
Traceback (most recent call last):
  File "D:\Task Management System Final code\Tasks\Update_Task.py", line 219, in send_for_review
    raise HTTPException(status_code=400, detail="Already sent for further review. Cannot send again.")
fastapi.exceptions.HTTPException: 400: Already sent for further review. Cannot send again.
2025-04-29 10:47:42,491 - send_for_review - INFO - POST /send_for_review called by user_id=1 for task_id=14
2025-04-29 10:47:42,523 - send_for_review - INFO - Review task 15 created successfully
2025-04-30 11:41:22,900 - send_for_review - INFO - POST /send_for_review called by user_id=1 for task_id=7
2025-04-30 11:41:22,949 - send_for_review - INFO - Review task 9 created successfully
2025-04-30 11:41:51,977 - send_for_review - INFO - POST /send_for_review called by user_id=1 for task_id=9
2025-04-30 11:41:52,009 - send_for_review - INFO - Review task 10 created successfully
2025-04-30 11:41:56,408 - send_for_review - INFO - POST /send_for_review called by user_id=1 for task_id=10
2025-04-30 11:41:56,445 - send_for_review - INFO - Review task 11 created successfully
2025-04-30 12:26:25,285 - send_for_review - INFO - POST /send_for_review called by user_id=1 for task_id=2
2025-04-30 12:26:25,314 - send_for_review - INFO - Review task 3 created successfully
2025-04-30 12:26:31,416 - send_for_review - INFO - POST /send_for_review called by user_id=1 for task_id=3
2025-04-30 12:26:31,443 - send_for_review - INFO - Review task 4 created successfully
2025-04-30 12:26:36,595 - send_for_review - INFO - POST /send_for_review called by user_id=1 for task_id=4
2025-04-30 12:26:36,627 - send_for_review - INFO - Review task 5 created successfully
2025-04-30 17:17:19,617 - send_for_review - INFO - POST /send_for_review called by user_id=2 for task_id=2
2025-04-30 17:17:19,661 - send_for_review - INFO - Review task 3 created successfully
2025-04-30 17:51:32,341 - send_for_review - INFO - POST /send_for_review called by user_id=2 for task_id=4
2025-04-30 17:51:32,349 - send_for_review - ERROR - Unexpected error while sending for review
Traceback (most recent call last):
  File "D:\Task Management System Final code\Tasks\Update_Task.py", line 206, in send_for_review
    raise HTTPException(status_code=400, detail="Only review tasks can send for further review.")
fastapi.exceptions.HTTPException: 400: Only review tasks can send for further review.
2025-04-30 17:51:35,456 - send_for_review - INFO - POST /send_for_review called by user_id=2 for task_id=5
2025-04-30 17:51:35,490 - send_for_review - INFO - Review task 6 created successfully
2025-05-01 19:28:27,431 - send_for_review - INFO - POST /send_for_review called by user_id=1 for task_id=8
2025-05-01 19:28:27,445 - send_for_review - WARNING - Task not found or unauthorized for user 1
2025-05-01 19:28:27,448 - send_for_review - ERROR - Unexpected error while sending for review
Traceback (most recent call last):
  File "D:\Task Management System Final code\Tasks\Update_Task.py", line 205, in send_for_review
    raise HTTPException(status_code=404, detail="Task not found or unauthorized")
fastapi.exceptions.HTTPException: 404: Task not found or unauthorized
2025-05-01 19:33:24,453 - send_for_review - INFO - POST /send_for_review called by user_id=1 for task_id=8
2025-05-01 19:33:24,494 - send_for_review - INFO - Review task 9 created successfully
2025-05-01 19:33:35,122 - send_for_review - INFO - POST /send_for_review called by user_id=1 for task_id=9
2025-05-01 19:33:35,163 - send_for_review - INFO - Review task 10 created successfully
2025-05-02 10:50:59,007 - send_for_review - INFO - POST /send_for_review called by user_id=1 for task_id=6
2025-05-02 10:50:59,032 - send_for_review - INFO - Marked task 6 as in review
2025-05-02 10:50:59,079 - send_for_review - INFO - Review task 7 created successfully
2025-05-02 13:12:42,064 - send_for_review - INFO - POST /send_for_review called by user_id=1 for task_id=2
2025-05-02 13:12:42,076 - send_for_review - INFO - Marked task 2 as in review
2025-05-02 13:12:42,092 - send_for_review - INFO - Review task 3 created successfully
2025-05-02 13:49:44,269 - send_for_review - INFO - POST /send_for_review called by user_id=1 for task_id=7
2025-05-02 13:49:44,278 - send_for_review - INFO - Marked task 7 as in review
2025-05-02 13:49:44,298 - send_for_review - INFO - Review task 8 created successfully
2025-05-02 18:03:45,624 - send_for_review - INFO - POST /send_for_review called by user_id=1 for task_id=10
2025-05-02 18:03:45,630 - send_for_review - INFO - Marked task 10 as in review
2025-05-02 18:03:45,645 - send_for_review - INFO - Review task 11 created successfully
2025-05-02 18:05:18,868 - send_for_review - INFO - POST /send_for_review called by user_id=1 for task_id=11
2025-05-02 18:05:18,884 - send_for_review - INFO - Marked task 11 as in review
2025-05-02 18:05:18,910 - send_for_review - INFO - Review task 12 created successfully
